Workbook
Name frmASM: 'Data Entry'!$D$9
Name frmCity: 'Data Entry'!$D$7
Name frmCommRate: Products!$G$3
Name frmDate: 'Data Entry'!$D$5
Name frmDesc: 'Data Entry'!$C$13:$C$24
Name frmInvNo: 'Data Entry'!$D$4
Name frmParty: 'Data Entry'!$D$6
Name frmQty: 'Data Entry'!$D$13:$D$24
Name frmR40: 'Data Entry'!$F$13:$F$24
Name frmSubParty: 'Data Entry'!$D$8
Name lstASM: 'OFFSET(Lists'!$C$2,'COUNTA(Lists'!$C$2:$C$500
Name lstCity: 'OFFSET(Lists'!$B$2,'COUNTA(Lists'!$B$2:$B$500
Name lstParty: 'OFFSET(Lists'!$A$2,'COUNTA(Lists'!$A$2:$A$500
Name lstProduct: 'OFFSET(Products'!$B$4,'COUNTA(Products'!$B$4:$B$500
Name lstSubParty: 'OFFSET(Lists'!$D$2,'COUNTA(Lists'!$D$2:$D$500

Sheet Data Entry
A1: ▦ | B1: WAQAR RICE MILLS | H1: SEPTEMBER 2026
B2: Shamshad Khan Shaheed Road, Kamoke · Sales Invoice Data Entry
B3: INVOICE DETAILS | F3: INVOICE SUMMARY
B4: Invoice No. | D4: 15
B5: Invoice Date | D5: 46267 | F5: Amount | I5: =$H$25 -> 1272188
B6: Party (Name) | D6: Pak Rice Traders | F6: Commission | I6: =$I$25 -> 4452.658
B7: City | D7: Dina | F7: Total Bags | I7: =$D$25 -> 200
B8: Sub Party
B9: ASM / Salesperson | D9: Farhan Khalid
B11: LINE ITEMS
B12: Sr | C12: Description (Product) | D12: Bags | E12: Pack Wt (KG) | F12: Rate 40Kg | G12: Rate / Pack | H12: AMOUNT | I12: Commission | J12: Weight (KG)
B13: 1 | C13: MASAR SABIT 25KG | D13: 30 | E13: =IFERROR(INDEX(Products!$E$4:$E$500,MATCH($C13,Products!$B$4:$B$500,0)),"") -> 25 | F13: 8000 | G13: =IF(OR($C13="",$F13=""),"",$F13/40*$E13) -> 5000 | H13: =IF(OR($G13="",$D13=""),"",ROUND($G13*$D13,0)) -> 150000 | I13: =IF($H13="","",$H13*IFERROR(INDEX(Products!$I$4:$I$500,MATCH($C13,Products!$B$4:$B$500,0)),frmCommRate)) -> 525 | J13: =IF($C13="","",$D13*$E13) -> 750
B14: 2 | C14: DAAL MASH CHARI 25KG | D14: 20 | E14: =IFERROR(INDEX(Products!$E$4:$E$500,MATCH($C14,Products!$B$4:$B$500,0)),"") -> 25 | F14: 16250 | G14: =IF(OR($C14="",$F14=""),"",$F14/40*$E14) -> 10156.25 | H14: =IF(OR($G14="",$D14=""),"",ROUND($G14*$D14,0)) -> 203125 | I14: =IF($H14="","",$H14*IFERROR(INDEX(Products!$I$4:$I$500,MATCH($C14,Products!$B$4:$B$500,0)),frmCommRate)) -> 710.9375 | J14: =IF($C14="","",$D14*$E14) -> 500
B15: 3 | C15: DAAL MOONG 25KG | D15: 30 | E15: =IFERROR(INDEX(Products!$E$4:$E$500,MATCH($C15,Products!$B$4:$B$500,0)),"") -> 25 | F15: 10250 | G15: =IF(OR($C15="",$F15=""),"",$F15/40*$E15) -> 6406.25 | H15: =IF(OR($G15="",$D15=""),"",ROUND($G15*$D15,0)) -> 192188 | I15: =IF($H15="","",$H15*IFERROR(INDEX(Products!$I$4:$I$500,MATCH($C15,Products!$B$4:$B$500,0)),frmCommRate)) -> 672.658 | J15: =IF($C15="","",$D15*$E15) -> 750
B16: 4 | C16: DALL MASOOR 25KG | D16: 20 | E16: =IFERROR(INDEX(Products!$E$4:$E$500,MATCH($C16,Products!$B$4:$B$500,0)),"") -> 25 | F16: 8400 | G16: =IF(OR($C16="",$F16=""),"",$F16/40*$E16) -> 5250 | H16: =IF(OR($G16="",$D16=""),"",ROUND($G16*$D16,0)) -> 105000 | I16: =IF($H16="","",$H16*IFERROR(INDEX(Products!$I$4:$I$500,MATCH($C16,Products!$B$4:$B$500,0)),frmCommRate)) -> 367.5 | J16: =IF($C16="","",$D16*$E16) -> 500
B17: 5 | C17: DAAL CHANNA SUPREME 25KG | D17: 100 | E17: =IFERROR(INDEX(Products!$E$4:$E$500,MATCH($C17,Products!$B$4:$B$500,0)),"") -> 25 | F17: 9950 | G17: =IF(OR($C17="",$F17=""),"",$F17/40*$E17) -> 6218.75 | H17: =IF(OR($G17="",$D17=""),"",ROUND($G17*$D17,0)) -> 621875 | I17: =IF($H17="","",$H17*IFERROR(INDEX(Products!$I$4:$I$500,MATCH($C17,Products!$B$4:$B$500,0)),frmCommRate)) -> 2176.5625 | J17: =IF($C17="","",$D17*$E17) -> 2500
B18: 6 | E18: =IFERROR(INDEX(Products!$E$4:$E$500,MATCH($C18,Products!$B$4:$B$500,0)),"") | G18: =IF(OR($C18="",$F18=""),"",$F18/40*$E18) | H18: =IF(OR($G18="",$D18=""),"",ROUND($G18*$D18,0)) | I18: =IF($H18="","",$H18*IFERROR(INDEX(Products!$I$4:$I$500,MATCH($C18,Products!$B$4:$B$500,0)),frmCommRate)) | J18: =IF($C18="","",$D18*$E18)
B19: 7 | E19: =IFERROR(INDEX(Products!$E$4:$E$500,MATCH($C19,Products!$B$4:$B$500,0)),"") | G19: =IF(OR($C19="",$F19=""),"",$F19/40*$E19) | H19: =IF(OR($G19="",$D19=""),"",ROUND($G19*$D19,0)) | I19: =IF($H19="","",$H19*IFERROR(INDEX(Products!$I$4:$I$500,MATCH($C19,Products!$B$4:$B$500,0)),frmCommRate)) | J19: =IF($C19="","",$D19*$E19)
B20: 8 | E20: =IFERROR(INDEX(Products!$E$4:$E$500,MATCH($C20,Products!$B$4:$B$500,0)),"") | G20: =IF(OR($C20="",$F20=""),"",$F20/40*$E20) | H20: =IF(OR($G20="",$D20=""),"",ROUND($G20*$D20,0)) | I20: =IF($H20="","",$H20*IFERROR(INDEX(Products!$I$4:$I$500,MATCH($C20,Products!$B$4:$B$500,0)),frmCommRate)) | J20: =IF($C20="","",$D20*$E20)
B21: 9 | E21: =IFERROR(INDEX(Products!$E$4:$E$500,MATCH($C21,Products!$B$4:$B$500,0)),"") | G21: =IF(OR($C21="",$F21=""),"",$F21/40*$E21) | H21: =IF(OR($G21="",$D21=""),"",ROUND($G21*$D21,0)) | I21: =IF($H21="","",$H21*IFERROR(INDEX(Products!$I$4:$I$500,MATCH($C21,Products!$B$4:$B$500,0)),frmCommRate)) | J21: =IF($C21="","",$D21*$E21)
B22: 10 | E22: =IFERROR(INDEX(Products!$E$4:$E$500,MATCH($C22,Products!$B$4:$B$500,0)),"") | G22: =IF(OR($C22="",$F22=""),"",$F22/40*$E22) | H22: =IF(OR($G22="",$D22=""),"",ROUND($G22*$D22,0)) | I22: =IF($H22="","",$H22*IFERROR(INDEX(Products!$I$4:$I$500,MATCH($C22,Products!$B$4:$B$500,0)),frmCommRate)) | J22: =IF($C22="","",$D22*$E22)
B23: 11 | E23: =IFERROR(INDEX(Products!$E$4:$E$500,MATCH($C23,Products!$B$4:$B$500,0)),"") | G23: =IF(OR($C23="",$F23=""),"",$F23/40*$E23) | H23: =IF(OR($G23="",$D23=""),"",ROUND($G23*$D23,0)) | I23: =IF($H23="","",$H23*IFERROR(INDEX(Products!$I$4:$I$500,MATCH($C23,Products!$B$4:$B$500,0)),frmCommRate)) | J23: =IF($C23="","",$D23*$E23)
B24: 12 | E24: =IFERROR(INDEX(Products!$E$4:$E$500,MATCH($C24,Products!$B$4:$B$500,0)),"") | G24: =IF(OR($C24="",$F24=""),"",$F24/40*$E24) | H24: =IF(OR($G24="",$D24=""),"",ROUND($G24*$D24,0)) | I24: =IF($H24="","",$H24*IFERROR(INDEX(Products!$I$4:$I$500,MATCH($C24,Products!$B$4:$B$500,0)),frmCommRate)) | J24: =IF($C24="","",$D24*$E24)
C25: INVOICE TOTAL | D25: =SUM($D$13:$D$24) -> 200 | H25: =SUM($H$13:$H$24) -> 1272188 | I25: =SUM($I$13:$I$24) -> 4452.658 | J25: =SUM($J$13:$J$24) -> 5000
B29: Fill the invoice above, then click SAVE / UPDATE. The invoice is written to the Database sheet - the grey columns there calculate themselves.

Sheet Dashboard
A2: ▦ | B2: WAQAR RICE MILLS | L2: SEPTEMBER 2026
B3: Shamshad Khan Shaheed Road, Kamoke · Sales Management System
B6: TOTAL REVENUE (PKR) | C6: ="▲ "&TEXT(IF($F$12=0,0,$B$7/$F$12),"0.0%")&" of target" -> ▲ 1.9% of target | E6: TOTAL COMMISSION | F6: ="▲ "&TEXT(IF($B$7=0,0,$E$7/$B$7),"0.00%")&" of sales" -> ▲ 0.35% of sales | H6: TOTAL WEIGHT (TONS) | I6: ="● "&TEXT(SUM(tblLines[Weight (KG)]),"#,##0")&" KG" -> ● 841,180 KG | K6: INVOICES | L6: ="● "&TEXT(SUM(tblLines[Qty (Packs)]),"#,##0")&" packs" -> ● 33,509 packs
B7: =SUM(tblLines[Amount]) -> 193457434 | E7: =SUM(tblLines[Commission]) -> 677101.02 | H7: =SUM(tblLines[Weight (KG)])/1000 -> 841.18 | K7: {=COUNTA(_xlfn.UNIQUE(_xlfn._xlws.FILTER(tblLines[Invoice '#],tblLines[Invoice '#]<>"")))} -> 35
B11: ANNUAL SALES TARGET
B12: Annual Sales Target (PKR) | F12: 10000000000 | H12: ← enter your annual target here
B13: Actual Sales to Date | F13: =$B$7 -> 193457434
B14: Achieved % | F14: =IF($F$12=0,"",F13/$F$12) -> 0.019345743 | K14: =F14 -> 0.019345743 | L14: =IFERROR(F14,0) -> 0.019345743
B15: Remaining to Target | F15: =IF($F$12=0,"",MAX(0,$F$12-F13)) -> 9806542566
B16: Implied Monthly Target | F16: =IF($F$12=0,"",$F$12/12) -> 8.3333333e+08
B20: SALES BY CATEGORY — RICE vs PULSES
B21: CATEGORY | E21: QTY (PACKS) | F21: WEIGHT (KG) | H21: AMOUNT (PKR) | I21: COMMISSION (PKR) | K21: % OF SALES | L21: SHARE
B22: Rice | E22: =SUMIF($M$48:$M$87,$B22,E$48:E$87) -> 31474 | F22: =SUMIF($M$48:$M$87,$B22,F$48:F$87) -> 790305 | H22: =SUMIF($M$48:$M$87,$B22,H$48:H$87) -> 180027193 | I22: =SUMIF($M$48:$M$87,$B22,I$48:I$87) -> 630095.18 | K22: =IF($B$7=0,"",H22/$B$7) -> 0.9305778 | L22: =IFERROR(K22,0) -> 0.9305778
B23: Pulses | E23: =SUMIF($M$48:$M$87,$B23,E$48:E$87) -> 2035 | F23: =SUMIF($M$48:$M$87,$B23,F$48:F$87) -> 50875 | H23: =SUMIF($M$48:$M$87,$B23,H$48:H$87) -> 13430241 | I23: =SUMIF($M$48:$M$87,$B23,I$48:I$87) -> 47005.844 | K23: =IF($B$7=0,"",H23/$B$7) -> 0.069422202 | L23: =IFERROR(K23,0) -> 0.069422202
B24: Other | E24: =SUMIF($M$48:$M$87,$B24,E$48:E$87) -> 0 | F24: =SUMIF($M$48:$M$87,$B24,F$48:F$87) -> 0 | H24: =SUMIF($M$48:$M$87,$B24,H$48:H$87) -> 0 | I24: =SUMIF($M$48:$M$87,$B24,I$48:I$87) -> 0 | K24: =IF($B$7=0,"",H24/$B$7) -> 0 | L24: =IFERROR(K24,0) -> 0
B25: TOTAL | E25: =SUM(E22:E24) -> 33509 | F25: =SUM(F22:F24) -> 841180 | H25: =SUM(H22:H24) -> 193457434 | I25: =SUM(I22:I24) -> 677101.02 | K25: =IF($B$7=0,"",H25/$B$7) -> 1
B29: SALES BY ASM / SALESPERSON
B30: ASM / SALESPERSON | E30: QTY (PACKS) | F30: WEIGHT (KG) | H30: AMOUNT (PKR) | I30: COMMISSION (PKR) | K30: % OF SALES | L30: SHARE
B31: {=_xlfn._xlws.SORT(_xlfn.UNIQUE(_xlfn._xlws.FILTER(TRIM(tblLines[ASM / Salesperson]),TRIM(tblLines[ASM / Salesperson])<>"")))} -> Arslan Ahmed Dar | E31: {=IF($B31="","",SUMPRODUCT((TRIM(tblLines[ASM / Salesperson])=$B31)*IF(ISNUMBER(tblLines[Qty (Packs)]),tblLines[Qty (Packs)],0)))} -> 3276 | F31: {=IF($B31="","",SUMPRODUCT((TRIM(tblLines[ASM / Salesperson])=$B31)*IF(ISNUMBER(tblLines[Weight (KG)]),tblLines[Weight (KG)],0)))} -> 82500 | H31: {=IF($B31="","",SUMPRODUCT((TRIM(tblLines[ASM / Salesperson])=$B31)*IF(ISNUMBER(tblLines[Amount]),tblLines[Amount],0)))} -> 24636878 | I31: {=IF($B31="","",SUMPRODUCT((TRIM(tblLines[ASM / Salesperson])=$B31)*IF(ISNUMBER(tblLines[Commission]),tblLines[Commission],0)))} -> 86229.073 | K31: =IF($B31="","",H31/$B$7) -> 0.12735038 | L31: =IFERROR(K31,0) -> 0.12735038
B32: Farhan Khalid | E32: {=IF($B32="","",SUMPRODUCT((TRIM(tblLines[ASM / Salesperson])=$B32)*IF(ISNUMBER(tblLines[Qty (Packs)]),tblLines[Qty (Packs)],0)))} -> 30233 | F32: {=IF($B32="","",SUMPRODUCT((TRIM(tblLines[ASM / Salesperson])=$B32)*IF(ISNUMBER(tblLines[Weight (KG)]),tblLines[Weight (KG)],0)))} -> 758680 | H32: {=IF($B32="","",SUMPRODUCT((TRIM(tblLines[ASM / Salesperson])=$B32)*IF(ISNUMBER(tblLines[Amount]),tblLines[Amount],0)))} -> 168820556 | I32: {=IF($B32="","",SUMPRODUCT((TRIM(tblLines[ASM / Salesperson])=$B32)*IF(ISNUMBER(tblLines[Commission]),tblLines[Commission],0)))} -> 590871.95 | K32: =IF($B32="","",H32/$B$7) -> 0.87264962 | L32: =IFERROR(K32,0) -> 0.87264962
E33: {=IF($B33="","",SUMPRODUCT((TRIM(tblLines[ASM / Salesperson])=$B33)*IF(ISNUMBER(tblLines[Qty (Packs)]),tblLines[Qty (Packs)],0)))} | F33: {=IF($B33="","",SUMPRODUCT((TRIM(tblLines[ASM / Salesperson])=$B33)*IF(ISNUMBER(tblLines[Weight (KG)]),tblLines[Weight (KG)],0)))} | H33: {=IF($B33="","",SUMPRODUCT((TRIM(tblLines[ASM / Salesperson])=$B33)*IF(ISNUMBER(tblLines[Amount]),tblLines[Amount],0)))} | I33: {=IF($B33="","",SUMPRODUCT((TRIM(tblLines[ASM / Salesperson])=$B33)*IF(ISNUMBER(tblLines[Commission]),tblLines[Commission],0)))} | K33: =IF($B33="","",H33/$B$7) | L33: =IFERROR(K33,0)
E34: {=IF($B34="","",SUMPRODUCT((TRIM(tblLines[ASM / Salesperson])=$B34)*IF(ISNUMBER(tblLines[Qty (Packs)]),tblLines[Qty (Packs)],0)))} | F34: {=IF($B34="","",SUMPRODUCT((TRIM(tblLines[ASM / Salesperson])=$B34)*IF(ISNUMBER(tblLines[Weight (KG)]),tblLines[Weight (KG)],0)))} | H34: {=IF($B34="","",SUMPRODUCT((TRIM(tblLines[ASM / Salesperson])=$B34)*IF(ISNUMBER(tblLines[Amount]),tblLines[Amount],0)))} | I34: {=IF($B34="","",SUMPRODUCT((TRIM(tblLines[ASM / Salesperson])=$B34)*IF(ISNUMBER(tblLines[Commission]),tblLines[Commission],0)))} | K34: =IF($B34="","",H34/$B$7) | L34: =IFERROR(K34,0)
E35: {=IF($B35="","",SUMPRODUCT((TRIM(tblLines[ASM / Salesperson])=$B35)*IF(ISNUMBER(tblLines[Qty (Packs)]),tblLines[Qty (Packs)],0)))} | F35: {=IF($B35="","",SUMPRODUCT((TRIM(tblLines[ASM / Salesperson])=$B35)*IF(ISNUMBER(tblLines[Weight (KG)]),tblLines[Weight (KG)],0)))} | H35: {=IF($B35="","",SUMPRODUCT((TRIM(tblLines[ASM / Salesperson])=$B35)*IF(ISNUMBER(tblLines[Amount]),tblLines[Amount],0)))} | I35: {=IF($B35="","",SUMPRODUCT((TRIM(tblLines[ASM / Salesperson])=$B35)*IF(ISNUMBER(tblLines[Commission]),tblLines[Commission],0)))} | K35: =IF($B35="","",H35/$B$7) | L35: =IFERROR(K35,0)
E36: {=IF($B36="","",SUMPRODUCT((TRIM(tblLines[ASM / Salesperson])=$B36)*IF(ISNUMBER(tblLines[Qty (Packs)]),tblLines[Qty (Packs)],0)))} | F36: {=IF($B36="","",SUMPRODUCT((TRIM(tblLines[ASM / Salesperson])=$B36)*IF(ISNUMBER(tblLines[Weight (KG)]),tblLines[Weight (KG)],0)))} | H36: {=IF($B36="","",SUMPRODUCT((TRIM(tblLines[ASM / Salesperson])=$B36)*IF(ISNUMBER(tblLines[Amount]),tblLines[Amount],0)))} | I36: {=IF($B36="","",SUMPRODUCT((TRIM(tblLines[ASM / Salesperson])=$B36)*IF(ISNUMBER(tblLines[Commission]),tblLines[Commission],0)))} | K36: =IF($B36="","",H36/$B$7) | L36: =IFERROR(K36,0)
E37: {=IF($B37="","",SUMPRODUCT((TRIM(tblLines[ASM / Salesperson])=$B37)*IF(ISNUMBER(tblLines[Qty (Packs)]),tblLines[Qty (Packs)],0)))} | F37: {=IF($B37="","",SUMPRODUCT((TRIM(tblLines[ASM / Salesperson])=$B37)*IF(ISNUMBER(tblLines[Weight (KG)]),tblLines[Weight (KG)],0)))} | H37: {=IF($B37="","",SUMPRODUCT((TRIM(tblLines[ASM / Salesperson])=$B37)*IF(ISNUMBER(tblLines[Amount]),tblLines[Amount],0)))} | I37: {=IF($B37="","",SUMPRODUCT((TRIM(tblLines[ASM / Salesperson])=$B37)*IF(ISNUMBER(tblLines[Commission]),tblLines[Commission],0)))} | K37: =IF($B37="","",H37/$B$7) | L37: =IFERROR(K37,0)
E38: {=IF($B38="","",SUMPRODUCT((TRIM(tblLines[ASM / Salesperson])=$B38)*IF(ISNUMBER(tblLines[Qty (Packs)]),tblLines[Qty (Packs)],0)))} | F38: {=IF($B38="","",SUMPRODUCT((TRIM(tblLines[ASM / Salesperson])=$B38)*IF(ISNUMBER(tblLines[Weight (KG)]),tblLines[Weight (KG)],0)))} | H38: {=IF($B38="","",SUMPRODUCT((TRIM(tblLines[ASM / Salesperson])=$B38)*IF(ISNUMBER(tblLines[Amount]),tblLines[Amount],0)))} | I38: {=IF($B38="","",SUMPRODUCT((TRIM(tblLines[ASM / Salesperson])=$B38)*IF(ISNUMBER(tblLines[Commission]),tblLines[Commission],0)))} | K38: =IF($B38="","",H38/$B$7) | L38: =IFERROR(K38,0)
E39: {=IF($B39="","",SUMPRODUCT((TRIM(tblLines[ASM / Salesperson])=$B39)*IF(ISNUMBER(tblLines[Qty (Packs)]),tblLines[Qty (Packs)],0)))} | F39: {=IF($B39="","",SUMPRODUCT((TRIM(tblLines[ASM / Salesperson])=$B39)*IF(ISNUMBER(tblLines[Weight (KG)]),tblLines[Weight (KG)],0)))} | H39: {=IF($B39="","",SUMPRODUCT((TRIM(tblLines[ASM / Salesperson])=$B39)*IF(ISNUMBER(tblLines[Amount]),tblLines[Amount],0)))} | I39: {=IF($B39="","",SUMPRODUCT((TRIM(tblLines[ASM / Salesperson])=$B39)*IF(ISNUMBER(tblLines[Commission]),tblLines[Commission],0)))} | K39: =IF($B39="","",H39/$B$7) | L39: =IFERROR(K39,0)
E40: {=IF($B40="","",SUMPRODUCT((TRIM(tblLines[ASM / Salesperson])=$B40)*IF(ISNUMBER(tblLines[Qty (Packs)]),tblLines[Qty (Packs)],0)))} | F40: {=IF($B40="","",SUMPRODUCT((TRIM(tblLines[ASM / Salesperson])=$B40)*IF(ISNUMBER(tblLines[Weight (KG)]),tblLines[Weight (KG)],0)))} | H40: {=IF($B40="","",SUMPRODUCT((TRIM(tblLines[ASM / Salesperson])=$B40)*IF(ISNUMBER(tblLines[Amount]),tblLines[Amount],0)))} | I40: {=IF($B40="","",SUMPRODUCT((TRIM(tblLines[ASM / Salesperson])=$B40)*IF(ISNUMBER(tblLines[Commission]),tblLines[Commission],0)))} | K40: =IF($B40="","",H40/$B$7) | L40: =IFERROR(K40,0)
E41: {=IF($B41="","",SUMPRODUCT((TRIM(tblLines[ASM / Salesperson])=$B41)*IF(ISNUMBER(tblLines[Qty (Packs)]),tblLines[Qty (Packs)],0)))} | F41: {=IF($B41="","",SUMPRODUCT((TRIM(tblLines[ASM / Salesperson])=$B41)*IF(ISNUMBER(tblLines[Weight (KG)]),tblLines[Weight (KG)],0)))} | H41: {=IF($B41="","",SUMPRODUCT((TRIM(tblLines[ASM / Salesperson])=$B41)*IF(ISNUMBER(tblLines[Amount]),tblLines[Amount],0)))} | I41: {=IF($B41="","",SUMPRODUCT((TRIM(tblLines[ASM / Salesperson])=$B41)*IF(ISNUMBER(tblLines[Commission]),tblLines[Commission],0)))} | K41: =IF($B41="","",H41/$B$7) | L41: =IFERROR(K41,0)
E42: {=IF($B42="","",SUMPRODUCT((TRIM(tblLines[ASM / Salesperson])=$B42)*IF(ISNUMBER(tblLines[Qty (Packs)]),tblLines[Qty (Packs)],0)))} | F42: {=IF($B42="","",SUMPRODUCT((TRIM(tblLines[ASM / Salesperson])=$B42)*IF(ISNUMBER(tblLines[Weight (KG)]),tblLines[Weight (KG)],0)))} | H42: {=IF($B42="","",SUMPRODUCT((TRIM(tblLines[ASM / Salesperson])=$B42)*IF(ISNUMBER(tblLines[Amount]),tblLines[Amount],0)))} | I42: {=IF($B42="","",SUMPRODUCT((TRIM(tblLines[ASM / Salesperson])=$B42)*IF(ISNUMBER(tblLines[Commission]),tblLines[Commission],0)))} | K42: =IF($B42="","",H42/$B$7) | L42: =IFERROR(K42,0)
B46: SALES BY PRODUCT
B47: PRODUCT | E47: QTY (PACKS) | F47: WEIGHT (KG) | H47: AMOUNT (PKR) | I47: COMMISSION (PKR) | K47: % OF SALES | L47: SHARE | M47: CATEGORY
B48: {=_xlfn._xlws.SORT(_xlfn.UNIQUE(_xlfn._xlws.FILTER(TRIM(tblLines[Description (Product)]),TRIM(tblLines[Description (Product)])<>"")))} -> DAAL CHANNA ECONOMY 25KG | E48: {=IF($B48="","",SUMPRODUCT((TRIM(tblLines[Description (Product)])=$B48)*IF(ISNUMBER(tblLines[Qty (Packs)]),tblLines[Qty (Packs)],0)))} -> 70 | F48: {=IF($B48="","",SUMPRODUCT((TRIM(tblLines[Description (Product)])=$B48)*IF(ISNUMBER(tblLines[Weight (KG)]),tblLines[Weight (KG)],0)))} -> 1750 | H48: {=IF($B48="","",SUMPRODUCT((TRIM(tblLines[Description (Product)])=$B48)*IF(ISNUMBER(tblLines[Amount]),tblLines[Amount],0)))} -> 365313 | I48: {=IF($B48="","",SUMPRODUCT((TRIM(tblLines[Description (Product)])=$B48)*IF(ISNUMBER(tblLines[Commission]),tblLines[Commission],0)))} -> 1278.5955 | K48: =IF($B48="","",H48/$B$7) -> 0.0018883379 | L48: =IFERROR(K48,0) -> 0.0018883379 | M48: =IF($B48="","",IFERROR(INDEX(Products!$H$4:$H$500,MATCH($B48,Products!$B$4:$B$500,0)),"Unmapped")) -> Pulses
B49: DAAL CHANNA REGULAR 25KG | E49: {=IF($B49="","",SUMPRODUCT((TRIM(tblLines[Description (Product)])=$B49)*IF(ISNUMBER(tblLines[Qty (Packs)]),tblLines[Qty (Packs)],0)))} -> 80 | F49: {=IF($B49="","",SUMPRODUCT((TRIM(tblLines[Description (Product)])=$B49)*IF(ISNUMBER(tblLines[Weight (KG)]),tblLines[Weight (KG)],0)))} -> 2000 | H49: {=IF($B49="","",SUMPRODUCT((TRIM(tblLines[Description (Product)])=$B49)*IF(ISNUMBER(tblLines[Amount]),tblLines[Amount],0)))} -> 452513 | I49: {=IF($B49="","",SUMPRODUCT((TRIM(tblLines[Description (Product)])=$B49)*IF(ISNUMBER(tblLines[Commission]),tblLines[Commission],0)))} -> 1583.7955 | K49: =IF($B49="","",H49/$B$7) -> 0.002339083 | L49: =IFERROR(K49,0) -> 0.002339083 | M49: =IF($B49="","",IFERROR(INDEX(Products!$H$4:$H$500,MATCH($B49,Products!$B$4:$B$500,0)),"Unmapped")) -> Pulses
B50: DAAL CHANNA SUPREME 25KG | E50: {=IF($B50="","",SUMPRODUCT((TRIM(tblLines[Description (Product)])=$B50)*IF(ISNUMBER(tblLines[Qty (Packs)]),tblLines[Qty (Packs)],0)))} -> 120 | F50: {=IF($B50="","",SUMPRODUCT((TRIM(tblLines[Description (Product)])=$B50)*IF(ISNUMBER(tblLines[Weight (KG)]),tblLines[Weight (KG)],0)))} -> 3000 | H50: {=IF($B50="","",SUMPRODUCT((TRIM(tblLines[Description (Product)])=$B50)*IF(ISNUMBER(tblLines[Amount]),tblLines[Amount],0)))} -> 747500 | I50: {=IF($B50="","",SUMPRODUCT((TRIM(tblLines[Description (Product)])=$B50)*IF(ISNUMBER(tblLines[Commission]),tblLines[Commission],0)))} -> 2616.25 | K50: =IF($B50="","",H50/$B$7) -> 0.0038638991 | L50: =IFERROR(K50,0) -> 0.0038638991 | M50: =IF($B50="","",IFERROR(INDEX(Products!$H$4:$H$500,MATCH($B50,Products!$B$4:$B$500,0)),"Unmapped")) -> Pulses
B51: DAAL MASH CHARI 25KG | E51: {=IF($B51="","",SUMPRODUCT((TRIM(tblLines[Description (Product)])=$B51)*IF(ISNUMBER(tblLines[Qty (Packs)]),tblLines[Qty (Packs)],0)))} -> 115 | F51: {=IF($B51="","",SUMPRODUCT((TRIM(tblLines[Description (Product)])=$B51)*IF(ISNUMBER(tblLines[Weight (KG)]),tblLines[Weight (KG)],0)))} -> 2875 | H51: {=IF($B51="","",SUMPRODUCT((TRIM(tblLines[Description (Product)])=$B51)*IF(ISNUMBER(tblLines[Amount]),tblLines[Amount],0)))} -> 1169244 | I51: {=IF($B51="","",SUMPRODUCT((TRIM(tblLines[Description (Product)])=$B51)*IF(ISNUMBER(tblLines[Commission]),tblLines[Commission],0)))} -> 4092.354 | K51: =IF($B51="","",H51/$B$7) -> 0.0060439342 | L51: =IFERROR(K51,0) -> 0.0060439342 | M51: =IF($B51="","",IFERROR(INDEX(Products!$H$4:$H$500,MATCH($B51,Products!$B$4:$B$500,0)),"Unmapped")) -> Pulses
B52: DAAL MOONG 25KG | E52: {=IF($B52="","",SUMPRODUCT((TRIM(tblLines[Description (Product)])=$B52)*IF(ISNUMBER(tblLines[Qty (Packs)]),tblLines[Qty (Packs)],0)))} -> 85 | F52: {=IF($B52="","",SUMPRODUCT((TRIM(tblLines[Description (Product)])=$B52)*IF(ISNUMBER(tblLines[Weight (KG)]),tblLines[Weight (KG)],0)))} -> 2125 | H52: {=IF($B52="","",SUMPRODUCT((TRIM(tblLines[Description (Product)])=$B52)*IF(ISNUMBER(tblLines[Amount]),tblLines[Amount],0)))} -> 545488 | I52: {=IF($B52="","",SUMPRODUCT((TRIM(tblLines[Description (Product)])=$B52)*IF(ISNUMBER(tblLines[Commission]),tblLines[Commission],0)))} -> 1909.208 | K52: =IF($B52="","",H52/$B$7) -> 0.0028196797 | L52: =IFERROR(K52,0) -> 0.0028196797 | M52: =IF($B52="","",IFERROR(INDEX(Products!$H$4:$H$500,MATCH($B52,Products!$B$4:$B$500,0)),"Unmapped")) -> Pulses
B53: DALL MASOOR 25KG | E53: {=IF($B53="","",SUMPRODUCT((TRIM(tblLines[Description (Product)])=$B53)*IF(ISNUMBER(tblLines[Qty (Packs)]),tblLines[Qty (Packs)],0)))} -> 115 | F53: {=IF($B53="","",SUMPRODUCT((TRIM(tblLines[Description (Product)])=$B53)*IF(ISNUMBER(tblLines[Weight (KG)]),tblLines[Weight (KG)],0)))} -> 2875 | H53: {=IF($B53="","",SUMPRODUCT((TRIM(tblLines[Description (Product)])=$B53)*IF(ISNUMBER(tblLines[Amount]),tblLines[Amount],0)))} -> 608281 | I53: {=IF($B53="","",SUMPRODUCT((TRIM(tblLines[Description (Product)])=$B53)*IF(ISNUMBER(tblLines[Commission]),tblLines[Commission],0)))} -> 2128.9835 | K53: =IF($B53="","",H53/$B$7) -> 0.0031442627 | L53: =IFERROR(K53,0) -> 0.0031442627 | M53: =IF($B53="","",IFERROR(INDEX(Products!$H$4:$H$500,MATCH($B53,Products!$B$4:$B$500,0)),"Unmapped")) -> Pulses
B54: HAZARA B-2, 25KG | E54: {=IF($B54="","",SUMPRODUCT((TRIM(tblLines[Description (Product)])=$B54)*IF(ISNUMBER(tblLines[Qty (Packs)]),tblLines[Qty (Packs)],0)))} -> 660 | F54: {=IF($B54="","",SUMPRODUCT((TRIM(tblLines[Description (Product)])=$B54)*IF(ISNUMBER(tblLines[Weight (KG)]),tblLines[Weight (KG)],0)))} -> 16500 | H54: {=IF($B54="","",SUMPRODUCT((TRIM(tblLines[Description (Product)])=$B54)*IF(ISNUMBER(tblLines[Amount]),tblLines[Amount],0)))} -> 1870626 | I54: {=IF($B54="","",SUMPRODUCT((TRIM(tblLines[Description (Product)])=$B54)*IF(ISNUMBER(tblLines[Commission]),tblLines[Commission],0)))} -> 6547.191 | K54: =IF($B54="","",H54/$B$7) -> 0.0096694449 | L54: =IFERROR(K54,0) -> 0.0096694449 | M54: =IF($B54="","",IFERROR(INDEX(Products!$H$4:$H$500,MATCH($B54,Products!$B$4:$B$500,0)),"Unmapped")) -> Rice
B55: KALAA CHANNA JAMBO 25KG | E55: {=IF($B55="","",SUMPRODUCT((TRIM(tblLines[Description (Product)])=$B55)*IF(ISNUMBER(tblLines[Qty (Packs)]),tblLines[Qty (Packs)],0)))} -> 45 | F55: {=IF($B55="","",SUMPRODUCT((TRIM(tblLines[Description (Product)])=$B55)*IF(ISNUMBER(tblLines[Weight (KG)]),tblLines[Weight (KG)],0)))} -> 1125 | H55: {=IF($B55="","",SUMPRODUCT((TRIM(tblLines[Description (Product)])=$B55)*IF(ISNUMBER(tblLines[Amount]),tblLines[Amount],0)))} -> 254844 | I55: {=IF($B55="","",SUMPRODUCT((TRIM(tblLines[Description (Product)])=$B55)*IF(ISNUMBER(tblLines[Commission]),tblLines[Commission],0)))} -> 891.954 | K55: =IF($B55="","",H55/$B$7) -> 0.001317313 | L55: =IFERROR(K55,0) -> 0.001317313 | M55: =IF($B55="","",IFERROR(INDEX(Products!$H$4:$H$500,MATCH($B55,Products!$B$4:$B$500,0)),"Unmapped")) -> Pulses
...

Sheet Database
A1: Invoice # | B1: Invoice Date | C1: Party (Name) | D1: Sub Party | E1: City | F1: ASM / Salesperson | G1: Description (Product) | H1: Qty (Packs) | I1: Rate 40Kg | J1: Pack Wt (KG) | K1: Rate / Pack | L1: Amount | M1: Commission | N1: Weight (KG)
A2: 6 | B2: 46266 | C2: Pak Rice Traders | E2: Dina | F2: Farhan Khalid | G2: ZAFARANI STEAM PLATINUM 25KG | H2: 125 | I2: 13500 | J2: =IFERROR(INDEX(Products!$E$4:$E$500,MATCH(tblLines[[#This Row],[Description (Product)]],Products!$B$4:$B$500,0)),"") -> 25 | K2: =IF(OR(tblLines[[#This Row],[Description (Product)]]="",tblLines[[#This Row],[Rate 40Kg]]=""),"",tblLines[[#This Row],[Rate 40Kg]]/40*tblLines[[#This Row],[Pack Wt (KG)]]) -> 8437.5 | L2: =IF(OR(tblLines[[#This Row],[Rate / Pack]]="",tblLines[[#This Row],[Qty (Packs)]]=""),"",ROUND(tblLines[[#This Row],[Rate / Pack]]*tblLines[[#This Row],[Qty (Packs)]],0)) -> 1054688 | M2: =IF(tblLines[[#This Row],[Amount]]="","",tblLines[[#This Row],[Amount]]*IFERROR(INDEX(Products!$I$4:$I$500,MATCH(tblLines[[#This Row],[Description (Product)]],Products!$B$4:$B$500,0)),frmCommRate)) -> 3691.408 | N2: =IF(tblLines[[#This Row],[Qty (Packs)]]="","",tblLines[[#This Row],[Qty (Packs)]]*tblLines[[#This Row],[Pack Wt (KG)]]) -> 3125
A3: 6 | B3: 46266 | C3: Pak Rice Traders | E3: Dina | F3: Farhan Khalid | G3: ZAFARANI SUTRANGI 25KG | H3: 200 | I3: 10600 | J3: =IFERROR(INDEX(Products!$E$4:$E$500,MATCH(tblLines[[#This Row],[Description (Product)]],Products!$B$4:$B$500,0)),"") -> 25 | K3: =IF(OR(tblLines[[#This Row],[Description (Product)]]="",tblLines[[#This Row],[Rate 40Kg]]=""),"",tblLines[[#This Row],[Rate 40Kg]]/40*tblLines[[#This Row],[Pack Wt (KG)]]) -> 6625 | L3: =IF(OR(tblLines[[#This Row],[Rate / Pack]]="",tblLines[[#This Row],[Qty (Packs)]]=""),"",ROUND(tblLines[[#This Row],[Rate / Pack]]*tblLines[[#This Row],[Qty (Packs)]],0)) -> 1325000 | M3: =IF(tblLines[[#This Row],[Amount]]="","",tblLines[[#This Row],[Amount]]*IFERROR(INDEX(Products!$I$4:$I$500,MATCH(tblLines[[#This Row],[Description (Product)]],Products!$B$4:$B$500,0)),frmCommRate)) -> 4637.5 | N3: =IF(tblLines[[#This Row],[Qty (Packs)]]="","",tblLines[[#This Row],[Qty (Packs)]]*tblLines[[#This Row],[Pack Wt (KG)]]) -> 5000
A4: 6 | B4: 46266 | C4: Pak Rice Traders | E4: Dina | F4: Farhan Khalid | G4: ZAFARANI STEAM B-1, 25KG | H4: 50 | I4: 7650 | J4: =IFERROR(INDEX(Products!$E$4:$E$500,MATCH(tblLines[[#This Row],[Description (Product)]],Products!$B$4:$B$500,0)),"") -> 25 | K4: =IF(OR(tblLines[[#This Row],[Description (Product)]]="",tblLines[[#This Row],[Rate 40Kg]]=""),"",tblLines[[#This Row],[Rate 40Kg]]/40*tblLines[[#This Row],[Pack Wt (KG)]]) -> 4781.25 | L4: =IF(OR(tblLines[[#This Row],[Rate / Pack]]="",tblLines[[#This Row],[Qty (Packs)]]=""),"",ROUND(tblLines[[#This Row],[Rate / Pack]]*tblLines[[#This Row],[Qty (Packs)]],0)) -> 239063 | M4: =IF(tblLines[[#This Row],[Amount]]="","",tblLines[[#This Row],[Amount]]*IFERROR(INDEX(Products!$I$4:$I$500,MATCH(tblLines[[#This Row],[Description (Product)]],Products!$B$4:$B$500,0)),frmCommRate)) -> 836.7205 | N4: =IF(tblLines[[#This Row],[Qty (Packs)]]="","",tblLines[[#This Row],[Qty (Packs)]]*tblLines[[#This Row],[Pack Wt (KG)]]) -> 1250
A5: 6 | B5: 46266 | C5: Pak Rice Traders | E5: Dina | F5: Farhan Khalid | G5: ZAFARANI SELLA GOLDEN 25KG | H5: 125 | I5: 12150 | J5: =IFERROR(INDEX(Products!$E$4:$E$500,MATCH(tblLines[[#This Row],[Description (Product)]],Products!$B$4:$B$500,0)),"") -> 25 | K5: =IF(OR(tblLines[[#This Row],[Description (Product)]]="",tblLines[[#This Row],[Rate 40Kg]]=""),"",tblLines[[#This Row],[Rate 40Kg]]/40*tblLines[[#This Row],[Pack Wt (KG)]]) -> 7593.75 | L5: =IF(OR(tblLines[[#This Row],[Rate / Pack]]="",tblLines[[#This Row],[Qty (Packs)]]=""),"",ROUND(tblLines[[#This Row],[Rate / Pack]]*tblLines[[#This Row],[Qty (Packs)]],0)) -> 949219 | M5: =IF(tblLines[[#This Row],[Amount]]="","",tblLines[[#This Row],[Amount]]*IFERROR(INDEX(Products!$I$4:$I$500,MATCH(tblLines[[#This Row],[Description (Product)]],Products!$B$4:$B$500,0)),frmCommRate)) -> 3322.2665 | N5: =IF(tblLines[[#This Row],[Qty (Packs)]]="","",tblLines[[#This Row],[Qty (Packs)]]*tblLines[[#This Row],[Pack Wt (KG)]]) -> 3125 | Q5: weight in tons | R5: =SUM(tblLines[Weight (KG)])/1000 -> 841.18
A6: 7 | B6: 46266 | C6: Pak Rice Traders | E6: Dina | F6: Farhan Khalid | G6: DAAL MOONG 25KG | H6: 25 | I6: 10250 | J6: =IFERROR(INDEX(Products!$E$4:$E$500,MATCH(tblLines[[#This Row],[Description (Product)]],Products!$B$4:$B$500,0)),"") -> 25 | K6: =IF(OR(tblLines[[#This Row],[Description (Product)]]="",tblLines[[#This Row],[Rate 40Kg]]=""),"",tblLines[[#This Row],[Rate 40Kg]]/40*tblLines[[#This Row],[Pack Wt (KG)]]) -> 6406.25 | L6: =IF(OR(tblLines[[#This Row],[Rate / Pack]]="",tblLines[[#This Row],[Qty (Packs)]]=""),"",ROUND(tblLines[[#This Row],[Rate / Pack]]*tblLines[[#This Row],[Qty (Packs)]],0)) -> 160156 | M6: =IF(tblLines[[#This Row],[Amount]]="","",tblLines[[#This Row],[Amount]]*IFERROR(INDEX(Products!$I$4:$I$500,MATCH(tblLines[[#This Row],[Description (Product)]],Products!$B$4:$B$500,0)),frmCommRate)) -> 560.546 | N6: =IF(tblLines[[#This Row],[Qty (Packs)]]="","",tblLines[[#This Row],[Qty (Packs)]]*tblLines[[#This Row],[Pack Wt (KG)]]) -> 625 | Q6: Total Sale | R6: =SUM(tblLines[Amount]) -> 193457434
A7: 7 | B7: 46266 | C7: Pak Rice Traders | E7: Dina | F7: Farhan Khalid | G7: DALL MASOOR 25KG | H7: 20 | I7: 8400 | J7: =IFERROR(INDEX(Products!$E$4:$E$500,MATCH(tblLines[[#This Row],[Description (Product)]],Products!$B$4:$B$500,0)),"") -> 25 | K7: =IF(OR(tblLines[[#This Row],[Description (Product)]]="",tblLines[[#This Row],[Rate 40Kg]]=""),"",tblLines[[#This Row],[Rate 40Kg]]/40*tblLines[[#This Row],[Pack Wt (KG)]]) -> 5250 | L7: =IF(OR(tblLines[[#This Row],[Rate / Pack]]="",tblLines[[#This Row],[Qty (Packs)]]=""),"",ROUND(tblLines[[#This Row],[Rate / Pack]]*tblLines[[#This Row],[Qty (Packs)]],0)) -> 105000 | M7: =IF(tblLines[[#This Row],[Amount]]="","",tblLines[[#This Row],[Amount]]*IFERROR(INDEX(Products!$I$4:$I$500,MATCH(tblLines[[#This Row],[Description (Product)]],Products!$B$4:$B$500,0)),frmCommRate)) -> 367.5 | N7: =IF(tblLines[[#This Row],[Qty (Packs)]]="","",tblLines[[#This Row],[Qty (Packs)]]*tblLines[[#This Row],[Pack Wt (KG)]]) -> 500 | Q7: commission | R7: =SUM(tblLines[Commission]) -> 677101.02
A8: 7 | B8: 46266 | C8: Pak Rice Traders | E8: Dina | F8: Farhan Khalid | G8: DAAL MASH CHARI 25KG | H8: 25 | I8: 16250 | J8: =IFERROR(INDEX(Products!$E$4:$E$500,MATCH(tblLines[[#This Row],[Description (Product)]],Products!$B$4:$B$500,0)),"") -> 25 | K8: =IF(OR(tblLines[[#This Row],[Description (Product)]]="",tblLines[[#This Row],[Rate 40Kg]]=""),"",tblLines[[#This Row],[Rate 40Kg]]/40*tblLines[[#This Row],[Pack Wt (KG)]]) -> 10156.25 | L8: =IF(OR(tblLines[[#This Row],[Rate / Pack]]="",tblLines[[#This Row],[Qty (Packs)]]=""),"",ROUND(tblLines[[#This Row],[Rate / Pack]]*tblLines[[#This Row],[Qty (Packs)]],0)) -> 253906 | M8: =IF(tblLines[[#This Row],[Amount]]="","",tblLines[[#This Row],[Amount]]*IFERROR(INDEX(Products!$I$4:$I$500,MATCH(tblLines[[#This Row],[Description (Product)]],Products!$B$4:$B$500,0)),frmCommRate)) -> 888.671 | N8: =IF(tblLines[[#This Row],[Qty (Packs)]]="","",tblLines[[#This Row],[Qty (Packs)]]*tblLines[[#This Row],[Pack Wt (KG)]]) -> 625 | Q8: Total Packs | R8: =SUM(tblLines[Qty (Packs)]) -> 33509
A9: 7 | B9: 46266 | C9: Pak Rice Traders | E9: Dina | F9: Farhan Khalid | G9: MASAR SABIT 25KG | H9: 30 | I9: 8000 | J9: =IFERROR(INDEX(Products!$E$4:$E$500,MATCH(tblLines[[#This Row],[Description (Product)]],Products!$B$4:$B$500,0)),"") -> 25 | K9: =IF(OR(tblLines[[#This Row],[Description (Product)]]="",tblLines[[#This Row],[Rate 40Kg]]=""),"",tblLines[[#This Row],[Rate 40Kg]]/40*tblLines[[#This Row],[Pack Wt (KG)]]) -> 5000 | L9: =IF(OR(tblLines[[#This Row],[Rate / Pack]]="",tblLines[[#This Row],[Qty (Packs)]]=""),"",ROUND(tblLines[[#This Row],[Rate / Pack]]*tblLines[[#This Row],[Qty (Packs)]],0)) -> 150000 | M9: =IF(tblLines[[#This Row],[Amount]]="","",tblLines[[#This Row],[Amount]]*IFERROR(INDEX(Products!$I$4:$I$500,MATCH(tblLines[[#This Row],[Description (Product)]],Products!$B$4:$B$500,0)),frmCommRate)) -> 525 | N9: =IF(tblLines[[#This Row],[Qty (Packs)]]="","",tblLines[[#This Row],[Qty (Packs)]]*tblLines[[#This Row],[Pack Wt (KG)]]) -> 750 | Q9: Avg of Ton | R9: =R6/R5 -> 229983.4
A10: 14 | B10: 46267 | C10: Pak Rice Traders | E10: Dina | F10: Farhan Khalid | G10: ZAFARANI STEAM PLATINUM 25KG | H10: 200 | I10: 13500 | J10: =IFERROR(INDEX(Products!$E$4:$E$500,MATCH(tblLines[[#This Row],[Description (Product)]],Products!$B$4:$B$500,0)),"") -> 25 | K10: =IF(OR(tblLines[[#This Row],[Description (Product)]]="",tblLines[[#This Row],[Rate 40Kg]]=""),"",tblLines[[#This Row],[Rate 40Kg]]/40*tblLines[[#This Row],[Pack Wt (KG)]]) -> 8437.5 | L10: =IF(OR(tblLines[[#This Row],[Rate / Pack]]="",tblLines[[#This Row],[Qty (Packs)]]=""),"",ROUND(tblLines[[#This Row],[Rate / Pack]]*tblLines[[#This Row],[Qty (Packs)]],0)) -> 1687500 | M10: =IF(tblLines[[#This Row],[Amount]]="","",tblLines[[#This Row],[Amount]]*IFERROR(INDEX(Products!$I$4:$I$500,MATCH(tblLines[[#This Row],[Description (Product)]],Products!$B$4:$B$500,0)),frmCommRate)) -> 5906.25 | N10: =IF(tblLines[[#This Row],[Qty (Packs)]]="","",tblLines[[#This Row],[Qty (Packs)]]*tblLines[[#This Row],[Pack Wt (KG)]]) -> 5000 | Q10: Avg of Pack | R10: =R6/R8 -> 5773.2977
A11: 14 | B11: 46267 | C11: Pak Rice Traders | E11: Dina | F11: Farhan Khalid | G11: ZAFARANI SUTRANGI 25KG | H11: 200 | I11: 10600 | J11: =IFERROR(INDEX(Products!$E$4:$E$500,MATCH(tblLines[[#This Row],[Description (Product)]],Products!$B$4:$B$500,0)),"") -> 25 | K11: =IF(OR(tblLines[[#This Row],[Description (Product)]]="",tblLines[[#This Row],[Rate 40Kg]]=""),"",tblLines[[#This Row],[Rate 40Kg]]/40*tblLines[[#This Row],[Pack Wt (KG)]]) -> 6625 | L11: =IF(OR(tblLines[[#This Row],[Rate / Pack]]="",tblLines[[#This Row],[Qty (Packs)]]=""),"",ROUND(tblLines[[#This Row],[Rate / Pack]]*tblLines[[#This Row],[Qty (Packs)]],0)) -> 1325000 | M11: =IF(tblLines[[#This Row],[Amount]]="","",tblLines[[#This Row],[Amount]]*IFERROR(INDEX(Products!$I$4:$I$500,MATCH(tblLines[[#This Row],[Description (Product)]],Products!$B$4:$B$500,0)),frmCommRate)) -> 4637.5 | N11: =IF(tblLines[[#This Row],[Qty (Packs)]]="","",tblLines[[#This Row],[Qty (Packs)]]*tblLines[[#This Row],[Pack Wt (KG)]]) -> 5000
A12: 15 | B12: 46267 | C12: Pak Rice Traders | E12: Dina | F12: Farhan Khalid | G12: MASAR SABIT 25KG | H12: 30 | I12: 8000 | J12: =IFERROR(INDEX(Products!$E$4:$E$500,MATCH(tblLines[[#This Row],[Description (Product)]],Products!$B$4:$B$500,0)),"") -> 25 | K12: =IF(OR(tblLines[[#This Row],[Description (Product)]]="",tblLines[[#This Row],[Rate 40Kg]]=""),"",tblLines[[#This Row],[Rate 40Kg]]/40*tblLines[[#This Row],[Pack Wt (KG)]]) -> 5000 | L12: =IF(OR(tblLines[[#This Row],[Rate / Pack]]="",tblLines[[#This Row],[Qty (Packs)]]=""),"",ROUND(tblLines[[#This Row],[Rate / Pack]]*tblLines[[#This Row],[Qty (Packs)]],0)) -> 150000 | M12: =IF(tblLines[[#This Row],[Amount]]="","",tblLines[[#This Row],[Amount]]*IFERROR(INDEX(Products!$I$4:$I$500,MATCH(tblLines[[#This Row],[Description (Product)]],Products!$B$4:$B$500,0)),frmCommRate)) -> 525 | N12: =IF(tblLines[[#This Row],[Qty (Packs)]]="","",tblLines[[#This Row],[Qty (Packs)]]*tblLines[[#This Row],[Pack Wt (KG)]]) -> 750
A13: 15 | B13: 46267 | C13: Pak Rice Traders | E13: Dina | F13: Farhan Khalid | G13: DAAL MASH CHARI 25KG | H13: 20 | I13: 16250 | J13: =IFERROR(INDEX(Products!$E$4:$E$500,MATCH(tblLines[[#This Row],[Description (Product)]],Products!$B$4:$B$500,0)),"") -> 25 | K13: =IF(OR(tblLines[[#This Row],[Description (Product)]]="",tblLines[[#This Row],[Rate 40Kg]]=""),"",tblLines[[#This Row],[Rate 40Kg]]/40*tblLines[[#This Row],[Pack Wt (KG)]]) -> 10156.25 | L13: =IF(OR(tblLines[[#This Row],[Rate / Pack]]="",tblLines[[#This Row],[Qty (Packs)]]=""),"",ROUND(tblLines[[#This Row],[Rate / Pack]]*tblLines[[#This Row],[Qty (Packs)]],0)) -> 203125 | M13: =IF(tblLines[[#This Row],[Amount]]="","",tblLines[[#This Row],[Amount]]*IFERROR(INDEX(Products!$I$4:$I$500,MATCH(tblLines[[#This Row],[Description (Product)]],Products!$B$4:$B$500,0)),frmCommRate)) -> 710.9375 | N13: =IF(tblLines[[#This Row],[Qty (Packs)]]="","",tblLines[[#This Row],[Qty (Packs)]]*tblLines[[#This Row],[Pack Wt (KG)]]) -> 500
A14: 15 | B14: 46267 | C14: Pak Rice Traders | E14: Dina | F14: Farhan Khalid | G14: DAAL MOONG 25KG | H14: 30 | I14: 10250 | J14: =IFERROR(INDEX(Products!$E$4:$E$500,MATCH(tblLines[[#This Row],[Description (Product)]],Products!$B$4:$B$500,0)),"") -> 25 | K14: =IF(OR(tblLines[[#This Row],[Description (Product)]]="",tblLines[[#This Row],[Rate 40Kg]]=""),"",tblLines[[#This Row],[Rate 40Kg]]/40*tblLines[[#This Row],[Pack Wt (KG)]]) -> 6406.25 | L14: =IF(OR(tblLines[[#This Row],[Rate / Pack]]="",tblLines[[#This Row],[Qty (Packs)]]=""),"",ROUND(tblLines[[#This Row],[Rate / Pack]]*tblLines[[#This Row],[Qty (Packs)]],0)) -> 192188 | M14: =IF(tblLines[[#This Row],[Amount]]="","",tblLines[[#This Row],[Amount]]*IFERROR(INDEX(Products!$I$4:$I$500,MATCH(tblLines[[#This Row],[Description (Product)]],Products!$B$4:$B$500,0)),frmCommRate)) -> 672.658 | N14: =IF(tblLines[[#This Row],[Qty (Packs)]]="","",tblLines[[#This Row],[Qty (Packs)]]*tblLines[[#This Row],[Pack Wt (KG)]]) -> 750
A15: 15 | B15: 46267 | C15: Pak Rice Traders | E15: Dina | F15: Farhan Khalid | G15: DALL MASOOR 25KG | H15: 20 | I15: 8400 | J15: =IFERROR(INDEX(Products!$E$4:$E$500,MATCH(tblLines[[#This Row],[Description (Product)]],Products!$B$4:$B$500,0)),"") -> 25 | K15: =IF(OR(tblLines[[#This Row],[Description (Product)]]="",tblLines[[#This Row],[Rate 40Kg]]=""),"",tblLines[[#This Row],[Rate 40Kg]]/40*tblLines[[#This Row],[Pack Wt (KG)]]) -> 5250 | L15: =IF(OR(tblLines[[#This Row],[Rate / Pack]]="",tblLines[[#This Row],[Qty (Packs)]]=""),"",ROUND(tblLines[[#This Row],[Rate / Pack]]*tblLines[[#This Row],[Qty (Packs)]],0)) -> 105000 | M15: =IF(tblLines[[#This Row],[Amount]]="","",tblLines[[#This Row],[Amount]]*IFERROR(INDEX(Products!$I$4:$I$500,MATCH(tblLines[[#This Row],[Description (Product)]],Products!$B$4:$B$500,0)),frmCommRate)) -> 367.5 | N15: =IF(tblLines[[#This Row],[Qty (Packs)]]="","",tblLines[[#This Row],[Qty (Packs)]]*tblLines[[#This Row],[Pack Wt (KG)]]) -> 500
A16: 15 | B16: 46267 | C16: Pak Rice Traders | E16: Dina | F16: Farhan Khalid | G16: DAAL CHANNA SUPREME 25KG | H16: 100 | I16: 9950 | J16: =IFERROR(INDEX(Products!$E$4:$E$500,MATCH(tblLines[[#This Row],[Description (Product)]],Products!$B$4:$B$500,0)),"") -> 25 | K16: =IF(OR(tblLines[[#This Row],[Description (Product)]]="",tblLines[[#This Row],[Rate 40Kg]]=""),"",tblLines[[#This Row],[Rate 40Kg]]/40*tblLines[[#This Row],[Pack Wt (KG)]]) -> 6218.75 | L16: =IF(OR(tblLines[[#This Row],[Rate / Pack]]="",tblLines[[#This Row],[Qty (Packs)]]=""),"",ROUND(tblLines[[#This Row],[Rate / Pack]]*tblLines[[#This Row],[Qty (Packs)]],0)) -> 621875 | M16: =IF(tblLines[[#This Row],[Amount]]="","",tblLines[[#This Row],[Amount]]*IFERROR(INDEX(Products!$I$4:$I$500,MATCH(tblLines[[#This Row],[Description (Product)]],Products!$B$4:$B$500,0)),frmCommRate)) -> 2176.5625 | N16: =IF(tblLines[[#This Row],[Qty (Packs)]]="","",tblLines[[#This Row],[Qty (Packs)]]*tblLines[[#This Row],[Pack Wt (KG)]]) -> 2500
A17: 16 | B17: 46267 | C17: Allah Walay Traders | E17: Nakyal Ajk | F17: Farhan Khalid | G17: ZAFARANI STEAM PLATINUM 25KG | H17: 200 | I17: 13700 | J17: =IFERROR(INDEX(Products!$E$4:$E$500,MATCH(tblLines[[#This Row],[Description (Product)]],Products!$B$4:$B$500,0)),"") -> 25 | K17: =IF(OR(tblLines[[#This Row],[Description (Product)]]="",tblLines[[#This Row],[Rate 40Kg]]=""),"",tblLines[[#This Row],[Rate 40Kg]]/40*tblLines[[#This Row],[Pack Wt (KG)]]) -> 8562.5 | L17: =IF(OR(tblLines[[#This Row],[Rate / Pack]]="",tblLines[[#This Row],[Qty (Packs)]]=""),"",ROUND(tblLines[[#This Row],[Rate / Pack]]*tblLines[[#This Row],[Qty (Packs)]],0)) -> 1712500 | M17: =IF(tblLines[[#This Row],[Amount]]="","",tblLines[[#This Row],[Amount]]*IFERROR(INDEX(Products!$I$4:$I$500,MATCH(tblLines[[#This Row],[Description (Product)]],Products!$B$4:$B$500,0)),frmCommRate)) -> 5993.75 | N17: =IF(tblLines[[#This Row],[Qty (Packs)]]="","",tblLines[[#This Row],[Qty (Packs)]]*tblLines[[#This Row],[Pack Wt (KG)]]) -> 5000
A18: 16 | B18: 46267 | C18: Allah Walay Traders | E18: Nakyal Ajk | F18: Farhan Khalid | G18: ZAFARANI STEAM SHORT GRAIN 25KG | H18: 50 | I18: 9000 | J18: =IFERROR(INDEX(Products!$E$4:$E$500,MATCH(tblLines[[#This Row],[Description (Product)]],Products!$B$4:$B$500,0)),"") -> 25 | K18: =IF(OR(tblLines[[#This Row],[Description (Product)]]="",tblLines[[#This Row],[Rate 40Kg]]=""),"",tblLines[[#This Row],[Rate 40Kg]]/40*tblLines[[#This Row],[Pack Wt (KG)]]) -> 5625 | L18: =IF(OR(tblLines[[#This Row],[Rate / Pack]]="",tblLines[[#This Row],[Qty (Packs)]]=""),"",ROUND(tblLines[[#This Row],[Rate / Pack]]*tblLines[[#This Row],[Qty (Packs)]],0)) -> 281250 | M18: =IF(tblLines[[#This Row],[Amount]]="","",tblLines[[#This Row],[Amount]]*IFERROR(INDEX(Products!$I$4:$I$500,MATCH(tblLines[[#This Row],[Description (Product)]],Products!$B$4:$B$500,0)),frmCommRate)) -> 984.375 | N18: =IF(tblLines[[#This Row],[Qty (Packs)]]="","",tblLines[[#This Row],[Qty (Packs)]]*tblLines[[#This Row],[Pack Wt (KG)]]) -> 1250
A19: 16 | B19: 46267 | C19: Allah Walay Traders | E19: Nakyal Ajk | F19: Farhan Khalid | G19: ZAFARANI STEAM B-1, 25KG | H19: 130 | I19: 7850 | J19: =IFERROR(INDEX(Products!$E$4:$E$500,MATCH(tblLines[[#This Row],[Description (Product)]],Products!$B$4:$B$500,0)),"") -> 25 | K19: =IF(OR(tblLines[[#This Row],[Description (Product)]]="",tblLines[[#This Row],[Rate 40Kg]]=""),"",tblLines[[#This Row],[Rate 40Kg]]/40*tblLines[[#This Row],[Pack Wt (KG)]]) -> 4906.25 | L19: =IF(OR(tblLines[[#This Row],[Rate / Pack]]="",tblLines[[#This Row],[Qty (Packs)]]=""),"",ROUND(tblLines[[#This Row],[Rate / Pack]]*tblLines[[#This Row],[Qty (Packs)]],0)) -> 637813 | M19: =IF(tblLines[[#This Row],[Amount]]="","",tblLines[[#This Row],[Amount]]*IFERROR(INDEX(Products!$I$4:$I$500,MATCH(tblLines[[#This Row],[Description (Product)]],Products!$B$4:$B$500,0)),frmCommRate)) -> 2232.3455 | N19: =IF(tblLines[[#This Row],[Qty (Packs)]]="","",tblLines[[#This Row],[Qty (Packs)]]*tblLines[[#This Row],[Pack Wt (KG)]]) -> 3250
A20: 16 | B20: 46267 | C20: Allah Walay Traders | E20: Nakyal Ajk | F20: Farhan Khalid | G20: ZAFARANI SELLA GOLDEN 25KG | H20: 50 | I20: 12900 | J20: =IFERROR(INDEX(Products!$E$4:$E$500,MATCH(tblLines[[#This Row],[Description (Product)]],Products!$B$4:$B$500,0)),"") -> 25 | K20: =IF(OR(tblLines[[#This Row],[Description (Product)]]="",tblLines[[#This Row],[Rate 40Kg]]=""),"",tblLines[[#This Row],[Rate 40Kg]]/40*tblLines[[#This Row],[Pack Wt (KG)]]) -> 8062.5 | L20: =IF(OR(tblLines[[#This Row],[Rate / Pack]]="",tblLines[[#This Row],[Qty (Packs)]]=""),"",ROUND(tblLines[[#This Row],[Rate / Pack]]*tblLines[[#This Row],[Qty (Packs)]],0)) -> 403125 | M20: =IF(tblLines[[#This Row],[Amount]]="","",tblLines[[#This Row],[Amount]]*IFERROR(INDEX(Products!$I$4:$I$500,MATCH(tblLines[[#This Row],[Description (Product)]],Products!$B$4:$B$500,0)),frmCommRate)) -> 1410.9375 | N20: =IF(tblLines[[#This Row],[Qty (Packs)]]="","",tblLines[[#This Row],[Qty (Packs)]]*tblLines[[#This Row],[Pack Wt (KG)]]) -> 1250
A21: 16 | B21: 46267 | C21: Allah Walay Traders | E21: Nakyal Ajk | F21: Farhan Khalid | G21: ZAFARANI STEAM B-2, 25KG | H21: 130 | I21: 6050 | J21: =IFERROR(INDEX(Products!$E$4:$E$500,MATCH(tblLines[[#This Row],[Description (Product)]],Products!$B$4:$B$500,0)),"") -> 25 | K21: =IF(OR(tblLines[[#This Row],[Description (Product)]]="",tblLines[[#This Row],[Rate 40Kg]]=""),"",tblLines[[#This Row],[Rate 40Kg]]/40*tblLines[[#This Row],[Pack Wt (KG)]]) -> 3781.25 | L21: =IF(OR(tblLines[[#This Row],[Rate / Pack]]="",tblLines[[#This Row],[Qty (Packs)]]=""),"",ROUND(tblLines[[#This Row],[Rate / Pack]]*tblLines[[#This Row],[Qty (Packs)]],0)) -> 491563 | M21: =IF(tblLines[[#This Row],[Amount]]="","",tblLines[[#This Row],[Amount]]*IFERROR(INDEX(Products!$I$4:$I$500,MATCH(tblLines[[#This Row],[Description (Product)]],Products!$B$4:$B$500,0)),frmCommRate)) -> 1720.4705 | N21: =IF(tblLines[[#This Row],[Qty (Packs)]]="","",tblLines[[#This Row],[Qty (Packs)]]*tblLines[[#This Row],[Pack Wt (KG)]]) -> 3250
A22: 16 | B22: 46267 | C22: Allah Walay Traders | E22: Nakyal Ajk | F22: Farhan Khalid | G22: ZAFARANI STEAM SHADMANI 25KG | H22: 50 | I22: 9900 | J22: =IFERROR(INDEX(Products!$E$4:$E$500,MATCH(tblLines[[#This Row],[Description (Product)]],Products!$B$4:$B$500,0)),"") -> 25 | K22: =IF(OR(tblLines[[#This Row],[Description (Product)]]="",tblLines[[#This Row],[Rate 40Kg]]=""),"",tblLines[[#This Row],[Rate 40Kg]]/40*tblLines[[#This Row],[Pack Wt (KG)]]) -> 6187.5 | L22: =IF(OR(tblLines[[#This Row],[Rate / Pack]]="",tblLines[[#This Row],[Qty (Packs)]]=""),"",ROUND(tblLines[[#This Row],[Rate / Pack]]*tblLines[[#This Row],[Qty (Packs)]],0)) -> 309375 | M22: =IF(tblLines[[#This Row],[Amount]]="","",tblLines[[#This Row],[Amount]]*IFERROR(INDEX(Products!$I$4:$I$500,MATCH(tblLines[[#This Row],[Description (Product)]],Products!$B$4:$B$500,0)),frmCommRate)) -> 1082.8125 | N22: =IF(tblLines[[#This Row],[Qty (Packs)]]="","",tblLines[[#This Row],[Qty (Packs)]]*tblLines[[#This Row],[Pack Wt (KG)]]) -> 1250
... A65: 90 | B65: 46273 | C65: Sheikh Traders | E65: Lalamusa | F65: Farhan Khalid | G65: MASAR SABIT 25KG | H65: 10 | I65: 8150 | J65: =IFERROR(INDEX(Products!$E$4:$E$500,MATCH(tblLines[[#This Row],[Description (Product)]],Products!$B$4:$B$500,0)),"") -> 25 | K65: =IF(OR(tblLines[[#This Row],[Description (Product)]]="",tblLines[[#This Row],[Rate 40Kg]]=""),"",tblLines[[#This Row],[Rate 40Kg]]/40*tblLines[[#This Row],[Pack Wt (KG)]]) -> 5093.75 | L65: =IF(OR(tblLines[[#This Row],[Rate / Pack]]="",tblLines[[#This Row],[Qty (Packs)]]=""),"",ROUND(tblLines[[#This Row],[Rate / Pack]]*tblLines[[#This Row],[Qty (Packs)]],0)) -> 50938 | M65: =IF(tblLines[[#This Row],[Amount]]="","",tblLines[[#This Row],[Amount]]*IFERROR(INDEX(Products!$I$4:$I$500,MATCH(tblLines[[#This Row],[Description (Product)]],Products!$B$4:$B$500,0)),frmCommRate)) -> 178.283 | N65: =IF(tblLines[[#This Row],[Qty (Packs)]]="","",tblLines[[#This Row],[Qty (Packs)]]*tblLines[[#This Row],[Pack Wt (KG)]]) -> 250
A66: 53 | B66: 46270 | C66: Pak Rice Traders | D66: M Zaman Kotli | E66: Dina | F66: Arslan Ahmed Dar | G66: ZAFARANI STEAM PLATINUM 25KG | H66: 550 | I66: 13500 | J66: =IFERROR(INDEX(Products!$E$4:$E$500,MATCH(tblLines[[#This Row],[Description (Product)]],Products!$B$4:$B$500,0)),"") -> 25 | K66: =IF(OR(tblLines[[#This Row],[Description (Product)]]="",tblLines[[#This Row],[Rate 40Kg]]=""),"",tblLines[[#This Row],[Rate 40Kg]]/40*tblLines[[#This Row],[Pack Wt (KG)]]) -> 8437.5 | L66: =IF(OR(tblLines[[#This Row],[Rate / Pack]]="",tblLines[[#This Row],[Qty (Packs)]]=""),"",ROUND(tblLines[[#This Row],[Rate / Pack]]*tblLines[[#This Row],[Qty (Packs)]],0)) -> 4640625 | M66: =IF(tblLines[[#This Row],[Amount]]="","",tblLines[[#This Row],[Amount]]*IFERROR(INDEX(Products!$I$4:$I$500,MATCH(tblLines[[#This Row],[Description (Product)]],Products!$B$4:$B$500,0)),frmCommRate)) -> 16242.188 | N66: =IF(tblLines[[#This Row],[Qty (Packs)]]="","",tblLines[[#This Row],[Qty (Packs)]]*tblLines[[#This Row],[Pack Wt (KG)]]) -> 13750
A67: 53 | B67: 46270 | C67: Pak Rice Traders | D67: M Zaman Kotli | E67: Dina | F67: Arslan Ahmed Dar | G67: ZAFARANI STEAM B-1, 25KG | H67: 200 | I67: 7650 | J67: =IFERROR(INDEX(Products!$E$4:$E$500,MATCH(tblLines[[#This Row],[Description (Product)]],Products!$B$4:$B$500,0)),"") -> 25 | K67: =IF(OR(tblLines[[#This Row],[Description (Product)]]="",tblLines[[#This Row],[Rate 40Kg]]=""),"",tblLines[[#This Row],[Rate 40Kg]]/40*tblLines[[#This Row],[Pack Wt (KG)]]) -> 4781.25 | L67: =IF(OR(tblLines[[#This Row],[Rate / Pack]]="",tblLines[[#This Row],[Qty (Packs)]]=""),"",ROUND(tblLines[[#This Row],[Rate / Pack]]*tblLines[[#This Row],[Qty (Packs)]],0)) -> 956250 | M67: =IF(tblLines[[#This Row],[Amount]]="","",tblLines[[#This Row],[Amount]]*IFERROR(INDEX(Products!$I$4:$I$500,MATCH(tblLines[[#This Row],[Description (Product)]],Products!$B$4:$B$500,0)),frmCommRate)) -> 3346.875 | N67: =IF(tblLines[[#This Row],[Qty (Packs)]]="","",tblLines[[#This Row],[Qty (Packs)]]*tblLines[[#This Row],[Pack Wt (KG)]]) -> 5000
A68: 67 | B68: 46272 | C68: Shalimar Traders | E68: Gilgit | F68: Farhan Khalid | G68: ZAFARANI STEAM B-1, 25KG | H68: 300 | I68: 7850 | J68: =IFERROR(INDEX(Products!$E$4:$E$500,MATCH(tblLines[[#This Row],[Description (Product)]],Products!$B$4:$B$500,0)),"") -> 25 | K68: =IF(OR(tblLines[[#This Row],[Description (Product)]]="",tblLines[[#This Row],[Rate 40Kg]]=""),"",tblLines[[#This Row],[Rate 40Kg]]/40*tblLines[[#This Row],[Pack Wt (KG)]]) -> 4906.25 | L68: =IF(OR(tblLines[[#This Row],[Rate / Pack]]="",tblLines[[#This Row],[Qty (Packs)]]=""),"",ROUND(tblLines[[#This Row],[Rate / Pack]]*tblLines[[#This Row],[Qty (Packs)]],0)) -> 1471875 | M68: =IF(tblLines[[#This Row],[Amount]]="","",tblLines[[#This Row],[Amount]]*IFERROR(INDEX(Products!$I$4:$I$500,MATCH(tblLines[[#This Row],[Description (Product)]],Products!$B$4:$B$500,0)),frmCommRate)) -> 5151.5625 | N68: =IF(tblLines[[#This Row],[Qty (Packs)]]="","",tblLines[[#This Row],[Qty (Packs)]]*tblLines[[#This Row],[Pack Wt (KG)]]) -> 7500
A69: 67 | B69: 46272 | C69: Shalimar Traders | E69: Gilgit | F69: Farhan Khalid | G69: ZAFARANI STEAM PLATINUM 25KG | H69: 260 | I69: 13500 | J69: =IFERROR(INDEX(Products!$E$4:$E$500,MATCH(tblLines[[#This Row],[Description (Product)]],Products!$B$4:$B$500,0)),"") -> 25 | K69: =IF(OR(tblLines[[#This Row],[Description (Product)]]="",tblLines[[#This Row],[Rate 40Kg]]=""),"",tblLines[[#This Row],[Rate 40Kg]]/40*tblLines[[#This Row],[Pack Wt (KG)]]) -> 8437.5 | L69: =IF(OR(tblLines[[#This Row],[Rate / Pack]]="",tblLines[[#This Row],[Qty (Packs)]]=""),"",ROUND(tblLines[[#This Row],[Rate / Pack]]*tblLines[[#This Row],[Qty (Packs)]],0)) -> 2193750 | M69: =IF(tblLines[[#This Row],[Amount]]="","",tblLines[[#This Row],[Amount]]*IFERROR(INDEX(Products!$I$4:$I$500,MATCH(tblLines[[#This Row],[Description (Product)]],Products!$B$4:$B$500,0)),frmCommRate)) -> 7678.125 | N69: =IF(tblLines[[#This Row],[Qty (Packs)]]="","",tblLines[[#This Row],[Qty (Packs)]]*tblLines[[#This Row],[Pack Wt (KG)]]) -> 6500
A70: 67 | B70: 46272 | C70: Shalimar Traders | E70: Gilgit | F70: Farhan Khalid | G70: ZAFARANI SELLA GOLDEN 25KG | H70: 200 | I70: 12350 | J70: =IFERROR(INDEX(Products!$E$4:$E$500,MATCH(tblLines[[#This Row],[Description (Product)]],Products!$B$4:$B$500,0)),"") -> 25 | K70: =IF(OR(tblLines[[#This Row],[Description (Product)]]="",tblLines[[#This Row],[Rate 40Kg]]=""),"",tblLines[[#This Row],[Rate 40Kg]]/40*tblLines[[#This Row],[Pack Wt (KG)]]) -> 7718.75 | L70: =IF(OR(tblLines[[#This Row],[Rate / Pack]]="",tblLines[[#This Row],[Qty (Packs)]]=""),"",ROUND(tblLines[[#This Row],[Rate / Pack]]*tblLines[[#This Row],[Qty (Packs)]],0)) -> 1543750 | M70: =IF(tblLines[[#This Row],[Amount]]="","",tblLines[[#This Row],[Amount]]*IFERROR(INDEX(Products!$I$4:$I$500,MATCH(tblLines[[#This Row],[Description (Product)]],Products!$B$4:$B$500,0)),frmCommRate)) -> 5403.125 | N70: =IF(tblLines[[#This Row],[Qty (Packs)]]="","",tblLines[[#This Row],[Qty (Packs)]]*tblLines[[#This Row],[Pack Wt (KG)]]) -> 5000
A71: 67 | B71: 46272 | C71: Shalimar Traders | E71: Gilgit | F71: Farhan Khalid | G71: ZAFARANI STEAM B-2, 25KG | H71: 200 | I71: 6050 | J71: =IFERROR(INDEX(Products!$E$4:$E$500,MATCH(tblLines[[#This Row],[Description (Product)]],Products!$B$4:$B$500,0)),"") -> 25 | K71: =IF(OR(tblLines[[#This Row],[Description (Product)]]="",tblLines[[#This Row],[Rate 40Kg]]=""),"",tblLines[[#This Row],[Rate 40Kg]]/40*tblLines[[#This Row],[Pack Wt (KG)]]) -> 3781.25 | L71: =IF(OR(tblLines[[#This Row],[Rate / Pack]]="",tblLines[[#This Row],[Qty (Packs)]]=""),"",ROUND(tblLines[[#This Row],[Rate / Pack]]*tblLines[[#This Row],[Qty (Packs)]],0)) -> 756250 | M71: =IF(tblLines[[#This Row],[Amount]]="","",tblLines[[#This Row],[Amount]]*IFERROR(INDEX(Products!$I$4:$I$500,MATCH(tblLines[[#This Row],[Description (Product)]],Products!$B$4:$B$500,0)),frmCommRate)) -> 2646.875 | N71: =IF(tblLines[[#This Row],[Qty (Packs)]]="","",tblLines[[#This Row],[Qty (Packs)]]*tblLines[[#This Row],[Pack Wt (KG)]]) -> 5000
A72: 68 | B72: 46272 | C72: Shalimar Traders | E72: Gilgit | F72: Farhan Khalid | G72: ZAFARANI LOBIA PINTO 25KG | H72: 480 | I72: 12000 | J72: =IFERROR(INDEX(Products!$E$4:$E$500,MATCH(tblLines[[#This Row],[Description (Product)]],Products!$B$4:$B$500,0)),"") -> 25 | K72: =IF(OR(tblLines[[#This Row],[Description (Product)]]="",tblLines[[#This Row],[Rate 40Kg]]=""),"",tblLines[[#This Row],[Rate 40Kg]]/40*tblLines[[#This Row],[Pack Wt (KG)]]) -> 7500 | L72: =IF(OR(tblLines[[#This Row],[Rate / Pack]]="",tblLines[[#This Row],[Qty (Packs)]]=""),"",ROUND(tblLines[[#This Row],[Rate / Pack]]*tblLines[[#This Row],[Qty (Packs)]],0)) -> 3600000 | M72: =IF(tblLines[[#This Row],[Amount]]="","",tblLines[[#This Row],[Amount]]*IFERROR(INDEX(Products!$I$4:$I$500,MATCH(tblLines[[#This Row],[Description (Product)]],Products!$B$4:$B$500,0)),frmCommRate)) -> 12600 | N72: =IF(tblLines[[#This Row],[Qty (Packs)]]="","",tblLines[[#This Row],[Qty (Packs)]]*tblLines[[#This Row],[Pack Wt (KG)]]) -> 12000
A73: 107 | B73: 46274 | C73: Allah Walay Traders | E73: Nakyal Ajk | F73: Farhan Khalid | G73: ZAFARANI STEAM GOLD 25KG | H73: 50 | I73: 12500 | J73: =IFERROR(INDEX(Products!$E$4:$E$500,MATCH(tblLines[[#This Row],[Description (Product)]],Products!$B$4:$B$500,0)),"") -> 25 | K73: =IF(OR(tblLines[[#This Row],[Description (Product)]]="",tblLines[[#This Row],[Rate 40Kg]]=""),"",tblLines[[#This Row],[Rate 40Kg]]/40*tblLines[[#This Row],[Pack Wt (KG)]]) -> 7812.5 | L73: =IF(OR(tblLines[[#This Row],[Rate / Pack]]="",tblLines[[#This Row],[Qty (Packs)]]=""),"",ROUND(tblLines[[#This Row],[Rate / Pack]]*tblLines[[#This Row],[Qty (Packs)]],0)) -> 390625 | M73: =IF(tblLines[[#This Row],[Amount]]="","",tblLines[[#This Row],[Amount]]*IFERROR(INDEX(Products!$I$4:$I$500,MATCH(tblLines[[#This Row],[Description (Product)]],Products!$B$4:$B$500,0)),frmCommRate)) -> 1367.1875 | N73: =IF(tblLines[[#This Row],[Qty (Packs)]]="","",tblLines[[#This Row],[Qty (Packs)]]*tblLines[[#This Row],[Pack Wt (KG)]]) -> 1250
A74: 107 | B74: 46274 | C74: Allah Walay Traders | E74: Nakyal Ajk | F74: Farhan Khalid | G74: ZAFARANI STEAM B-2, 25KG | H74: 100 | I74: 5900 | J74: =IFERROR(INDEX(Products!$E$4:$E$500,MATCH(tblLines[[#This Row],[Description (Product)]],Products!$B$4:$B$500,0)),"") -> 25 | K74: =IF(OR(tblLines[[#This Row],[Description (Product)]]="",tblLines[[#This Row],[Rate 40Kg]]=""),"",tblLines[[#This Row],[Rate 40Kg]]/40*tblLines[[#This Row],[Pack Wt (KG)]]) -> 3687.5 | L74: =IF(OR(tblLines[[#This Row],[Rate / Pack]]="",tblLines[[#This Row],[Qty (Packs)]]=""),"",ROUND(tblLines[[#This Row],[Rate / Pack]]*tblLines[[#This Row],[Qty (Packs)]],0)) -> 368750 | M74: =IF(tblLines[[#This Row],[Amount]]="","",tblLines[[#This Row],[Amount]]*IFERROR(INDEX(Products!$I$4:$I$500,MATCH(tblLines[[#This Row],[Description (Product)]],Products!$B$4:$B$500,0)),frmCommRate)) -> 1290.625 | N74: =IF(tblLines[[#This Row],[Qty (Packs)]]="","",tblLines[[#This Row],[Qty (Packs)]]*tblLines[[#This Row],[Pack Wt (KG)]]) -> 2500
A75: 107 | B75: 46274 | C75: Allah Walay Traders | E75: Nakyal Ajk | F75: Farhan Khalid | G75: ZAFARANI STEAM PLATINUM 25KG | H75: 340 | I75: 13300 | J75: =IFERROR(INDEX(Products!$E$4:$E$500,MATCH(tblLines[[#This Row],[Description (Product)]],Products!$B$4:$B$500,0)),"") -> 25 | K75: =IF(OR(tblLines[[#This Row],[Description (Product)]]="",tblLines[[#This Row],[Rate 40Kg]]=""),"",tblLines[[#This Row],[Rate 40Kg]]/40*tblLines[[#This Row],[Pack Wt (KG)]]) -> 8312.5 | L75: =IF(OR(tblLines[[#This Row],[Rate / Pack]]="",tblLines[[#This Row],[Qty (Packs)]]=""),"",ROUND(tblLines[[#This Row],[Rate / Pack]]*tblLines[[#This Row],[Qty (Packs)]],0)) -> 2826250 | M75: =IF(tblLines[[#This Row],[Amount]]="","",tblLines[[#This Row],[Amount]]*IFERROR(INDEX(Products!$I$4:$I$500,MATCH(tblLines[[#This Row],[Description (Product)]],Products!$B$4:$B$500,0)),frmCommRate)) -> 9891.875 | N75: =IF(tblLines[[#This Row],[Qty (Packs)]]="","",tblLines[[#This Row],[Qty (Packs)]]*tblLines[[#This Row],[Pack Wt (KG)]]) -> 8500
A76: 107 | B76: 46274 | C76: Allah Walay Traders | E76: Nakyal Ajk | F76: Farhan Khalid | G76: ZAFARANI SUTRANGI 25KG | H76: 50 | I76: 10600 | J76: =IFERROR(INDEX(Products!$E$4:$E$500,MATCH(tblLines[[#This Row],[Description (Product)]],Products!$B$4:$B$500,0)),"") -> 25 | K76: =IF(OR(tblLines[[#This Row],[Description (Product)]]="",tblLines[[#This Row],[Rate 40Kg]]=""),"",tblLines[[#This Row],[Rate 40Kg]]/40*tblLines[[#This Row],[Pack Wt (KG)]]) -> 6625 | L76: =IF(OR(tblLines[[#This Row],[Rate / Pack]]="",tblLines[[#This Row],[Qty (Packs)]]=""),"",ROUND(tblLines[[#This Row],[Rate / Pack]]*tblLines[[#This Row],[Qty (Packs)]],0)) -> 331250 | M76: =IF(tblLines[[#This Row],[Amount]]="","",tblLines[[#This Row],[Amount]]*IFERROR(INDEX(Products!$I$4:$I$500,MATCH(tblLines[[#This Row],[Description (Product)]],Products!$B$4:$B$500,0)),frmCommRate)) -> 1159.375 | N76: =IF(tblLines[[#This Row],[Qty (Packs)]]="","",tblLines[[#This Row],[Qty (Packs)]]*tblLines[[#This Row],[Pack Wt (KG)]]) -> 1250
A77: 107 | B77: 46274 | C77: Allah Walay Traders | E77: Nakyal Ajk | F77: Farhan Khalid | G77: ZAFARANI STEAM SHADMANI 25KG | H77: 50 | I77: 9900 | J77: =IFERROR(INDEX(Products!$E$4:$E$500,MATCH(tblLines[[#This Row],[Description (Product)]],Products!$B$4:$B$500,0)),"") -> 25 | K77: =IF(OR(tblLines[[#This Row],[Description (Product)]]="",tblLines[[#This Row],[Rate 40Kg]]=""),"",tblLines[[#This Row],[Rate 40Kg]]/40*tblLines[[#This Row],[Pack Wt (KG)]]) -> 6187.5 | L77: =IF(OR(tblLines[[#This Row],[Rate / Pack]]="",tblLines[[#This Row],[Qty (Packs)]]=""),"",ROUND(tblLines[[#This Row],[Rate / Pack]]*tblLines[[#This Row],[Qty (Packs)]],0)) -> 309375 | M77: =IF(tblLines[[#This Row],[Amount]]="","",tblLines[[#This Row],[Amount]]*IFERROR(INDEX(Products!$I$4:$I$500,MATCH(tblLines[[#This Row],[Description (Product)]],Products!$B$4:$B$500,0)),frmCommRate)) -> 1082.8125 | N77: =IF(tblLines[[#This Row],[Qty (Packs)]]="","",tblLines[[#This Row],[Qty (Packs)]]*tblLines[[#This Row],[Pack Wt (KG)]]) -> 1250
A78: 107 | B78: 46274 | C78: Allah Walay Traders | E78: Nakyal Ajk | F78: Farhan Khalid | G78: ZAFARANI SELLA GOLDEN 25KG | H78: 50 | I78: 12150 | J78: =IFERROR(INDEX(Products!$E$4:$E$500,MATCH(tblLines[[#This Row],[Description (Product)]],Products!$B$4:$B$500,0)),"") -> 25 | K78: =IF(OR(tblLines[[#This Row],[Description (Product)]]="",tblLines[[#This Row],[Rate 40Kg]]=""),"",tblLines[[#This Row],[Rate 40Kg]]/40*tblLines[[#This Row],[Pack Wt (KG)]]) -> 7593.75 | L78: =IF(OR(tblLines[[#This Row],[Rate / Pack]]="",tblLines[[#This Row],[Qty (Packs)]]=""),"",ROUND(tblLines[[#This Row],[Rate / Pack]]*tblLines[[#This Row],[Qty (Packs)]],0)) -> 379688 | M78: =IF(tblLines[[#This Row],[Amount]]="","",tblLines[[#This Row],[Amount]]*IFERROR(INDEX(Products!$I$4:$I$500,MATCH(tblLines[[#This Row],[Description (Product)]],Products!$B$4:$B$500,0)),frmCommRate)) -> 1328.908 | N78: =IF(tblLines[[#This Row],[Qty (Packs)]]="","",tblLines[[#This Row],[Qty (Packs)]]*tblLines[[#This Row],[Pack Wt (KG)]]) -> 1250
A79: 110 | B79: 46274 | C79: Hamdard Traders | E79: Gahkuch | F79: Farhan Khalid | G79: ZAFARANI STEAM B-2, 25KG | H79: 75 | I79: 6050 | J79: =IFERROR(INDEX(Products!$E$4:$E$500,MATCH(tblLines[[#This Row],[Description (Product)]],Products!$B$4:$B$500,0)),"") -> 25 | K79: =IF(OR(tblLines[[#This Row],[Description (Product)]]="",tblLines[[#This Row],[Rate 40Kg]]=""),"",tblLines[[#This Row],[Rate 40Kg]]/40*tblLines[[#This Row],[Pack Wt (KG)]]) -> 3781.25 | L79: =IF(OR(tblLines[[#This Row],[Rate / Pack]]="",tblLines[[#This Row],[Qty (Packs)]]=""),"",ROUND(tblLines[[#This Row],[Rate / Pack]]*tblLines[[#This Row],[Qty (Packs)]],0)) -> 283594 | M79: =IF(tblLines[[#This Row],[Amount]]="","",tblLines[[#This Row],[Amount]]*IFERROR(INDEX(Products!$I$4:$I$500,MATCH(tblLines[[#This Row],[Description (Product)]],Products!$B$4:$B$500,0)),frmCommRate)) -> 992.579 | N79: =IF(tblLines[[#This Row],[Qty (Packs)]]="","",tblLines[[#This Row],[Qty (Packs)]]*tblLines[[#This Row],[Pack Wt (KG)]]) -> 1875
